Workbook

Sheet Gestao
A1: ID | B1: Hora de início | C1: Hora de conclusão | D1: Nome do avaliador | E1: Área avaliada | F1: Código do produto | G1: Coluna1 | H1: Tipo incidente | I1: ANO/MÊS | J1: ENDEREÇO CORRIGIDO | K1: TURNO
A2: 1 | B2: 45722.406 | C2: 45722.407 | D2: RAFAEL | E2: Picking | G2: =VLOOKUP(F2,Produtos!A:B,2,FALSE) -> #N/A | H2: Microfuro | I2: =YEAR(Table1[[#This Row],[Hora de início]])&"/"&IF(MONTH(Table1[[#This Row],[Hora de início]])<10,"0"&MONTH(Table1[[#This Row],[Hora de início]]),MONTH(Table1[[#This Row],[Hora de início]])) -> 2025/03 | J2: =VLOOKUP(Table1[[#This Row],[Área avaliada]],Endereços!A:B,2,0) -> Picking Alto Giro | K2: =VLOOKUP(Table1[[#This Row],[Nome do avaliador ]],M:N,2,0) -> A
A3: 2 | B3: 45723.428 | C3: 45723.429 | D3: KETLYN | E3: Regulador 1 | G3: =VLOOKUP(F3,Produtos!A:B,2,FALSE) -> #N/A | H3: Microfuro | I3: =YEAR(Table1[[#This Row],[Hora de início]])&"/"&IF(MONTH(Table1[[#This Row],[Hora de início]])<10,"0"&MONTH(Table1[[#This Row],[Hora de início]]),MONTH(Table1[[#This Row],[Hora de início]])) -> 2025/03 | J3: =VLOOKUP(Table1[[#This Row],[Área avaliada]],Endereços!A:B,2,0) -> Área Verde | K3: =VLOOKUP(Table1[[#This Row],[Nome do avaliador ]],M:N,2,0) -> A
A4: 3 | B4: 45723.446 | C4: 45723.447 | D4: KETLYN | E4: Regulador 1 | G4: =VLOOKUP(F4,Produtos!A:B,2,FALSE) -> #N/A | H4: Microfuro | I4: =YEAR(Table1[[#This Row],[Hora de início]])&"/"&IF(MONTH(Table1[[#This Row],[Hora de início]])<10,"0"&MONTH(Table1[[#This Row],[Hora de início]]),MONTH(Table1[[#This Row],[Hora de início]])) -> 2025/03 | J4: =VLOOKUP(Table1[[#This Row],[Área avaliada]],Endereços!A:B,2,0) -> Área Verde | K4: =VLOOKUP(Table1[[#This Row],[Nome do avaliador ]],M:N,2,0) -> A | M4: CARLOS | N4: B
A5: 4 | B5: 45723.447 | C5: 45723.448 | D5: CLEBER | E5: Picking | G5: =VLOOKUP(F5,Produtos!A:B,2,FALSE) -> #N/A | H5: Microfuro | I5: =YEAR(Table1[[#This Row],[Hora de início]])&"/"&IF(MONTH(Table1[[#This Row],[Hora de início]])<10,"0"&MONTH(Table1[[#This Row],[Hora de início]]),MONTH(Table1[[#This Row],[Hora de início]])) -> 2025/03 | J5: =VLOOKUP(Table1[[#This Row],[Área avaliada]],Endereços!A:B,2,0) -> Picking Alto Giro | K5: =VLOOKUP(Table1[[#This Row],[Nome do avaliador ]],M:N,2,0) -> C | M5: LUCIANE | N5: A
A6: 5 | B6: 45735.41 | C6: 45735.416 | D6: RAFAEL | E6: RACK01 | G6: =VLOOKUP(F6,Produtos!A:B,2,FALSE) -> #N/A | H6: Microfuro | I6: =YEAR(Table1[[#This Row],[Hora de início]])&"/"&IF(MONTH(Table1[[#This Row],[Hora de início]])<10,"0"&MONTH(Table1[[#This Row],[Hora de início]]),MONTH(Table1[[#This Row],[Hora de início]])) -> 2025/03 | J6: =VLOOKUP(Table1[[#This Row],[Área avaliada]],Endereços!A:B,2,0) -> Área Verde | K6: =VLOOKUP(Table1[[#This Row],[Nome do avaliador ]],M:N,2,0) -> A | M6: LAISA | N6: A
A7: 6 | B7: 45735.416 | C7: 45735.417 | D7: TAINÁ | E7: Picking Baixo Giro | G7: =VLOOKUP(F7,Produtos!A:B,2,FALSE) -> #N/A | H7: Microfuro | I7: =YEAR(Table1[[#This Row],[Hora de início]])&"/"&IF(MONTH(Table1[[#This Row],[Hora de início]])<10,"0"&MONTH(Table1[[#This Row],[Hora de início]]),MONTH(Table1[[#This Row],[Hora de início]])) -> 2025/03 | J7: =VLOOKUP(Table1[[#This Row],[Área avaliada]],Endereços!A:B,2,0) -> Picking Baixo Giro | K7: =VLOOKUP(Table1[[#This Row],[Nome do avaliador ]],M:N,2,0) -> A | M7: JOSÉ GILNEI | N7: B
A8: 7 | B8: 45735.454 | C8: 45735.456 | D8: RAFAEL | E8: Picking Alto Giro | G8: =VLOOKUP(F8,Produtos!A:B,2,FALSE) -> #N/A | H8: Microfuro | I8: =YEAR(Table1[[#This Row],[Hora de início]])&"/"&IF(MONTH(Table1[[#This Row],[Hora de início]])<10,"0"&MONTH(Table1[[#This Row],[Hora de início]]),MONTH(Table1[[#This Row],[Hora de início]])) -> 2025/03 | J8: =VLOOKUP(Table1[[#This Row],[Área avaliada]],Endereços!A:B,2,0) -> Picking Alto Giro | K8: A | M8: RAFAEL | N8: A
A9: 8 | B9: 45735.456 | C9: 45735.457 | D9: NARCISO | E9: Picking Baixo Giro | G9: =VLOOKUP(F9,Produtos!A:B,2,FALSE) -> #N/A | H9: Microfuro | I9: =YEAR(Table1[[#This Row],[Hora de início]])&"/"&IF(MONTH(Table1[[#This Row],[Hora de início]])<10,"0"&MONTH(Table1[[#This Row],[Hora de início]]),MONTH(Table1[[#This Row],[Hora de início]])) -> 2025/03 | J9: =VLOOKUP(Table1[[#This Row],[Área avaliada]],Endereços!A:B,2,0) -> Picking Baixo Giro | K9: =VLOOKUP(Table1[[#This Row],[Nome do avaliador ]],M:N,2,0) -> A | M9: NARCISO | N9: A
A10: 9 | B10: 45735.457 | C10: 45735.458 | D10: JHOSLLEY | E10: Marketplace | G10: =VLOOKUP(F10,Produtos!A:B,2,FALSE) -> #N/A | H10: Filme rasgado | I10: =YEAR(Table1[[#This Row],[Hora de início]])&"/"&IF(MONTH(Table1[[#This Row],[Hora de início]])<10,"0"&MONTH(Table1[[#This Row],[Hora de início]]),MONTH(Table1[[#This Row],[Hora de início]])) -> 2025/03 | J10: =VLOOKUP(Table1[[#This Row],[Área avaliada]],Endereços!A:B,2,0) -> Área Vermelho | K10: A | M10: BRUNO | N10: B
A11: 10 | B11: 45735.458 | C11: 45735.458 | D11: LUCIANE | E11: Reg2RGB | G11: =VLOOKUP(F11,Produtos!A:B,2,FALSE) -> #N/A | H11: Filme rasgado | I11: =YEAR(Table1[[#This Row],[Hora de início]])&"/"&IF(MONTH(Table1[[#This Row],[Hora de início]])<10,"0"&MONTH(Table1[[#This Row],[Hora de início]]),MONTH(Table1[[#This Row],[Hora de início]])) -> 2025/03 | J11: =VLOOKUP(Table1[[#This Row],[Área avaliada]],Endereços!A:B,2,0) -> Área Azul | K11: =VLOOKUP(Table1[[#This Row],[Nome do avaliador ]],M:N,2,0) -> A | M11: KETLYN | N11: A
A12: 11 | B12: 45735.459 | C12: 45735.46 | D12: BRUNO | E12: RACK01 | G12: =VLOOKUP(F12,Produtos!A:B,2,FALSE) -> #N/A | H12: Filme rasgado | I12: =YEAR(Table1[[#This Row],[Hora de início]])&"/"&IF(MONTH(Table1[[#This Row],[Hora de início]])<10,"0"&MONTH(Table1[[#This Row],[Hora de início]]),MONTH(Table1[[#This Row],[Hora de início]])) -> 2025/03 | J12: =VLOOKUP(Table1[[#This Row],[Área avaliada]],Endereços!A:B,2,0) -> Área Verde | K12: =VLOOKUP(Table1[[#This Row],[Nome do avaliador ]],M:N,2,0) -> B | M12: TAINÁ | N12: A
A13: 12 | B13: 45735.46 | C13: 45735.461 | D13: CARLOS | E13: Reg4Lata | G13: =VLOOKUP(F13,Produtos!A:B,2,FALSE) -> #N/A | H13: Filme rasgado | I13: =YEAR(Table1[[#This Row],[Hora de início]])&"/"&IF(MONTH(Table1[[#This Row],[Hora de início]])<10,"0"&MONTH(Table1[[#This Row],[Hora de início]]),MONTH(Table1[[#This Row],[Hora de início]])) -> 2025/03 | J13: =VLOOKUP(Table1[[#This Row],[Área avaliada]],Endereços!A:B,2,0) -> Área Azul | K13: =VLOOKUP(Table1[[#This Row],[Nome do avaliador ]],M:N,2,0) -> B | M13: MARCIO | N13: C
A14: 13 | B14: 45735.461 | C14: 45735.462 | D14: GILBERTO | E14: RegPET | G14: =VLOOKUP(F14,Produtos!A:B,2,FALSE) -> #N/A | H14: Filme rasgado | I14: =YEAR(Table1[[#This Row],[Hora de início]])&"/"&IF(MONTH(Table1[[#This Row],[Hora de início]])<10,"0"&MONTH(Table1[[#This Row],[Hora de início]]),MONTH(Table1[[#This Row],[Hora de início]])) -> 2025/03 | J14: =VLOOKUP(Table1[[#This Row],[Área avaliada]],Endereços!A:B,2,0) -> Área Azul | K14: B | M14: FÁBIO | N14: C
A15: 14 | B15: 45735.462 | C15: 45735.463 | D15: RODRIGO | E15: RACK01 | G15: =VLOOKUP(F15,Produtos!A:B,2,FALSE) -> #N/A | H15: Filme rasgado | I15: =YEAR(Table1[[#This Row],[Hora de início]])&"/"&IF(MONTH(Table1[[#This Row],[Hora de início]])<10,"0"&MONTH(Table1[[#This Row],[Hora de início]]),MONTH(Table1[[#This Row],[Hora de início]])) -> 2025/03 | J15: =VLOOKUP(Table1[[#This Row],[Área avaliada]],Endereços!A:B,2,0) -> Área Verde | K15: =VLOOKUP(Table1[[#This Row],[Nome do avaliador ]],M:N,2,0) -> C | M15: JOSÉ | N15: B
A16: 15 | B16: 45735.463 | C16: 45735.465 | D16: MARCIO | E16: Picking Baixo Giro | G16: =VLOOKUP(F16,Produtos!A:B,2,FALSE) -> #N/A | H16: Filme rasgado | I16: =YEAR(Table1[[#This Row],[Hora de início]])&"/"&IF(MONTH(Table1[[#This Row],[Hora de início]])<10,"0"&MONTH(Table1[[#This Row],[Hora de início]]),MONTH(Table1[[#This Row],[Hora de início]])) -> 2025/03 | J16: =VLOOKUP(Table1[[#This Row],[Área avaliada]],Endereços!A:B,2,0) -> Picking Baixo Giro | K16: =VLOOKUP(Table1[[#This Row],[Nome do avaliador ]],M:N,2,0) -> C | M16: CLEBER | N16: C
A17: 16 | B17: 45735.465 | C17: 45735.466 | D17: LAISA | E17: Picking Alto Giro | G17: =VLOOKUP(F17,Produtos!A:B,2,FALSE) -> #N/A | H17: Filme rasgado | I17: =YEAR(Table1[[#This Row],[Hora de início]])&"/"&IF(MONTH(Table1[[#This Row],[Hora de início]])<10,"0"&MONTH(Table1[[#This Row],[Hora de início]]),MONTH(Table1[[#This Row],[Hora de início]])) -> 2025/03 | J17: =VLOOKUP(Table1[[#This Row],[Área avaliada]],Endereços!A:B,2,0) -> Picking Alto Giro | K17: =VLOOKUP(Table1[[#This Row],[Nome do avaliador ]],M:N,2,0) -> A | M17: RODRIGO | N17: C
A18: 17 | B18: 45735.466 | C18: 45735.467 | D18: JOSÉ GILNEI | E18: Picking Baixo Giro | G18: =VLOOKUP(F18,Produtos!A:B,2,FALSE) -> #N/A | H18: Filme rasgado | I18: =YEAR(Table1[[#This Row],[Hora de início]])&"/"&IF(MONTH(Table1[[#This Row],[Hora de início]])<10,"0"&MONTH(Table1[[#This Row],[Hora de início]]),MONTH(Table1[[#This Row],[Hora de início]])) -> 2025/03 | J18: =VLOOKUP(Table1[[#This Row],[Área avaliada]],Endereços!A:B,2,0) -> Picking Baixo Giro | K18: =VLOOKUP(Table1[[#This Row],[Nome do avaliador ]],M:N,2,0) -> B | M18: EDURADO | N18: B
A19: 18 | B19: 45735.467 | C19: 45735.468 | D19: FÁBIO | E19: RegPET | G19: =VLOOKUP(F19,Produtos!A:B,2,FALSE) -> #N/A | H19: Filme rasgado | I19: =YEAR(Table1[[#This Row],[Hora de início]])&"/"&IF(MONTH(Table1[[#This Row],[Hora de início]])<10,"0"&MONTH(Table1[[#This Row],[Hora de início]]),MONTH(Table1[[#This Row],[Hora de início]])) -> 2025/03 | J19: =VLOOKUP(Table1[[#This Row],[Área avaliada]],Endereços!A:B,2,0) -> Área Azul | K19: =VLOOKUP(Table1[[#This Row],[Nome do avaliador ]],M:N,2,0) -> C | M19: ROGÉRIO | N19: B
A20: 19 | B20: 45735.468 | C20: 45735.469 | D20: KETLYN | E20: RACK01 | G20: =VLOOKUP(F20,Produtos!A:B,2,FALSE) -> #N/A | H20: Filme rasgado | I20: =YEAR(Table1[[#This Row],[Hora de início]])&"/"&IF(MONTH(Table1[[#This Row],[Hora de início]])<10,"0"&MONTH(Table1[[#This Row],[Hora de início]]),MONTH(Table1[[#This Row],[Hora de início]])) -> 2025/03 | J20: =VLOOKUP(Table1[[#This Row],[Área avaliada]],Endereços!A:B,2,0) -> Área Verde | K20: =VLOOKUP(Table1[[#This Row],[Nome do avaliador ]],M:N,2,0) -> A | M20: GABRIEL | N20: B
A21: 20 | B21: 45735.469 | C21: 45735.469 | D21: CLEBER | E21: Picking Alto Giro | G21: =VLOOKUP(F21,Produtos!A:B,2,FALSE) -> #N/A | H21: Filme rasgado | I21: =YEAR(Table1[[#This Row],[Hora de início]])&"/"&IF(MONTH(Table1[[#This Row],[Hora de início]])<10,"0"&MONTH(Table1[[#This Row],[Hora de início]]),MONTH(Table1[[#This Row],[Hora de início]])) -> 2025/03 | J21: =VLOOKUP(Table1[[#This Row],[Área avaliada]],Endereços!A:B,2,0) -> Picking Alto Giro | K21: =VLOOKUP(Table1[[#This Row],[Nome do avaliador ]],M:N,2,0) -> C
A22: 21 | B22: 45735.469 | C22: 45735.47 | D22: TAINÁ | E22: Reg4Lata | G22: =VLOOKUP(F22,Produtos!A:B,2,FALSE) -> #N/A | H22: Filme rasgado | I22: =YEAR(Table1[[#This Row],[Hora de início]])&"/"&IF(MONTH(Table1[[#This Row],[Hora de início]])<10,"0"&MONTH(Table1[[#This Row],[Hora de início]]),MONTH(Table1[[#This Row],[Hora de início]])) -> 2025/03 | J22: =VLOOKUP(Table1[[#This Row],[Área avaliada]],Endereços!A:B,2,0) -> Área Azul | K22: =VLOOKUP(Table1[[#This Row],[Nome do avaliador ]],M:N,2,0) -> A
A23: 22 | B23: 45737.672 | C23: 45737.675 | D23: TAINÁ | E23: Reg4Lata | G23: =VLOOKUP(F23,Produtos!A:B,2,FALSE) -> #N/A | H23: Filme rasgado | I23: =YEAR(Table1[[#This Row],[Hora de início]])&"/"&IF(MONTH(Table1[[#This Row],[Hora de início]])<10,"0"&MONTH(Table1[[#This Row],[Hora de início]]),MONTH(Table1[[#This Row],[Hora de início]])) -> 2025/03 | J23: =VLOOKUP(Table1[[#This Row],[Área avaliada]],Endereços!A:B,2,0) -> Área Azul | K23: =VLOOKUP(Table1[[#This Row],[Nome do avaliador ]],M:N,2,0) -> A
A24: 23 | B24: 45737.676 | C24: 45737.678 | D24: TAINÁ | E24: Reg4Lata | G24: =VLOOKUP(F24,Produtos!A:B,2,FALSE) -> #N/A | H24: Avaria | I24: =YEAR(Table1[[#This Row],[Hora de início]])&"/"&IF(MONTH(Table1[[#This Row],[Hora de início]])<10,"0"&MONTH(Table1[[#This Row],[Hora de início]]),MONTH(Table1[[#This Row],[Hora de início]])) -> 2025/03 | J24: =VLOOKUP(Table1[[#This Row],[Área avaliada]],Endereços!A:B,2,0) -> Área Azul | K24: =VLOOKUP(Table1[[#This Row],[Nome do avaliador ]],M:N,2,0) -> A
A25: 24 | B25: 45740.443 | C25: 45740.444 | D25: TAINÁ | E25: RegPET | G25: =VLOOKUP(F25,Produtos!A:B,2,FALSE) -> #N/A | H25: Avaria | I25: =YEAR(Table1[[#This Row],[Hora de início]])&"/"&IF(MONTH(Table1[[#This Row],[Hora de início]])<10,"0"&MONTH(Table1[[#This Row],[Hora de início]]),MONTH(Table1[[#This Row],[Hora de início]])) -> 2025/03 | J25: =VLOOKUP(Table1[[#This Row],[Área avaliada]],Endereços!A:B,2,0) -> Área Azul | K25: =VLOOKUP(Table1[[#This Row],[Nome do avaliador ]],M:N,2,0) -> A
A26: 25 | B26: 45747.86 | C26: 45747.867 | D26: BRUNO | E26: Picking Baixo Giro | G26: =VLOOKUP(F26,Produtos!A:B,2,FALSE) -> #N/A | H26: Avaria | I26: =YEAR(Table1[[#This Row],[Hora de início]])&"/"&IF(MONTH(Table1[[#This Row],[Hora de início]])<10,"0"&MONTH(Table1[[#This Row],[Hora de início]]),MONTH(Table1[[#This Row],[Hora de início]])) -> 2025/03 | J26: =VLOOKUP(Table1[[#This Row],[Área avaliada]],Endereços!A:B,2,0) -> Picking Baixo Giro | K26: =VLOOKUP(Table1[[#This Row],[Nome do avaliador ]],M:N,2,0) -> B
A27: 26 | B27: 45748.762 | C27: 45748.776 | D27: JOSÉ GILNEI | E27: Picking Alto Giro | G27: =VLOOKUP(F27,Produtos!A:B,2,FALSE) -> #N/A | H27: Avaria | I27: =YEAR(Table1[[#This Row],[Hora de início]])&"/"&IF(MONTH(Table1[[#This Row],[Hora de início]])<10,"0"&MONTH(Table1[[#This Row],[Hora de início]]),MONTH(Table1[[#This Row],[Hora de início]])) -> 2025/04 | J27: =VLOOKUP(Table1[[#This Row],[Área avaliada]],Endereços!A:B,2,0) -> Picking Alto Giro | K27: =VLOOKUP(Table1[[#This Row],[Nome do avaliador ]],M:N,2,0) -> B
A28: 27 | B28: 45751.709 | C28: 45751.731 | D28: LAISA | E28: Picking Baixo Giro | G28: =VLOOKUP(F28,Produtos!A:B,2,FALSE) -> #N/A | H28: Avaria | I28: =YEAR(Table1[[#This Row],[Hora de início]])&"/"&IF(MONTH(Table1[[#This Row],[Hora de início]])<10,"0"&MONTH(Table1[[#This Row],[Hora de início]]),MONTH(Table1[[#This Row],[Hora de início]])) -> 2025/04 | J28: =VLOOKUP(Table1[[#This Row],[Área avaliada]],Endereços!A:B,2,0) -> Picking Baixo Giro | K28: =VLOOKUP(Table1[[#This Row],[Nome do avaliador ]],M:N,2,0) -> A
A29: 28 | B29: 45757.818 | C29: 45757.832 | D29: JOSÉ GILNEI | E29: Marketplace | G29: =VLOOKUP(F29,Produtos!A:B,2,FALSE) -> #N/A | H29: Avaria | I29: =YEAR(Table1[[#This Row],[Hora de início]])&"/"&IF(MONTH(Table1[[#This Row],[Hora de início]])<10,"0"&MONTH(Table1[[#This Row],[Hora de início]]),MONTH(Table1[[#This Row],[Hora de início]])) -> 2025/04 | J29: =VLOOKUP(Table1[[#This Row],[Área avaliada]],Endereços!A:B,2,0) -> Área Vermelho | K29: =VLOOKUP(Table1[[#This Row],[Nome do avaliador ]],M:N,2,0) -> B
A30: 29 | B30: 45764.641 | C30: 45764.645 | D30: JOSÉ GILNEI | E30: Picking Alto Giro | G30: =VLOOKUP(F30,Produtos!A:B,2,FALSE) -> #N/A | H30: Avaria | I30: =YEAR(Table1[[#This Row],[Hora de início]])&"/"&IF(MONTH(Table1[[#This Row],[Hora de início]])<10,"0"&MONTH(Table1[[#This Row],[Hora de início]]),MONTH(Table1[[#This Row],[Hora de início]])) -> 2025/04 | J30: =VLOOKUP(Table1[[#This Row],[Área avaliada]],Endereços!A:B,2,0) -> Picking Alto Giro | K30: =VLOOKUP(Table1[[#This Row],[Nome do avaliador ]],M:N,2,0) -> B
A31: 30 | B31: 45764.705 | C31: 45764.707 | D31: BRUNO | E31: Camera F | G31: =VLOOKUP(F31,Produtos!A:B,2,FALSE) -> #N/A | H31: Avaria | I31: =YEAR(Table1[[#This Row],[Hora de início]])&"/"&IF(MONTH(Table1[[#This Row],[Hora de início]])<10,"0"&MONTH(Table1[[#This Row],[Hora de início]]),MONTH(Table1[[#This Row],[Hora de início]])) -> 2025/04 | J31: =VLOOKUP(Table1[[#This Row],[Área avaliada]],Endereços!A:B,2,0) -> Área Vermelho | K31: =VLOOKUP(Table1[[#This Row],[Nome do avaliador ]],M:N,2,0) -> B
A32: 31 | B32: 45765.606 | C32: 45765.608 | D32: LAISA | E32: Picking Baixo Giro | G32: =VLOOKUP(F32,Produtos!A:B,2,FALSE) -> #N/A | H32: Avaria | I32: =YEAR(Table1[[#This Row],[Hora de início]])&"/"&IF(MONTH(Table1[[#This Row],[Hora de início]])<10,"0"&MONTH(Table1[[#This Row],[Hora de início]]),MONTH(Table1[[#This Row],[Hora de início]])) -> 2025/04 | J32: =VLOOKUP(Table1[[#This Row],[Área avaliada]],Endereços!A:B,2,0) -> Picking Baixo Giro | K32: =VLOOKUP(Table1[[#This Row],[Nome do avaliador ]],M:N,2,0) -> A
... A36: 35 | B36: 45777.442 | C36: 45777.443 | D36: BRUNO | E36: Camera F | G36: =VLOOKUP(F36,Produtos!A:B,2,FALSE) -> #N/A | H36: Avaria | I36: =YEAR(Table1[[#This Row],[Hora de início]])&"/"&IF(MONTH(Table1[[#This Row],[Hora de início]])<10,"0"&MONTH(Table1[[#This Row],[Hora de início]]),MONTH(Table1[[#This Row],[Hora de início]])) -> 2025/04 | J36: =VLOOKUP(Table1[[#This Row],[Área avaliada]],Endereços!A:B,2,0) -> Área Vermelho | K36: =VLOOKUP(Table1[[#This Row],[Nome do avaliador ]],M:N,2,0) -> B
A37: 36 | B37: 45785.347 | C37: 45785.391 | D37: JHOSLLEY | E37: Reg4Lata | G37: =VLOOKUP(F37,Produtos!A:B,2,FALSE) -> #N/A | H37: Avaria | I37: =YEAR(Table1[[#This Row],[Hora de início]])&"/"&IF(MONTH(Table1[[#This Row],[Hora de início]])<10,"0"&MONTH(Table1[[#This Row],[Hora de início]]),MONTH(Table1[[#This Row],[Hora de início]])) -> 2025/05 | J37: =VLOOKUP(Table1[[#This Row],[Área avaliada]],Endereços!A:B,2,0) -> Área Azul | K37: A
A38: 37 | B38: 45785.394 | C38: 45785.395 | D38: JHOSLLEY | E38: Reg4Lata | G38: =VLOOKUP(F38,Produtos!A:B,2,FALSE) -> #N/A | H38: Avaria | I38: =YEAR(Table1[[#This Row],[Hora de início]])&"/"&IF(MONTH(Table1[[#This Row],[Hora de início]])<10,"0"&MONTH(Table1[[#This Row],[Hora de início]]),MONTH(Table1[[#This Row],[Hora de início]])) -> 2025/05 | J38: =VLOOKUP(Table1[[#This Row],[Área avaliada]],Endereços!A:B,2,0) -> Área Azul
A39: 38 | B39: 45785.395 | C39: 45785.396 | D39: JHOSLLEY | E39: Reg4Lata | G39: =VLOOKUP(F39,Produtos!A:B,2,FALSE) -> #N/A | H39: Avaria | I39: =YEAR(Table1[[#This Row],[Hora de início]])&"/"&IF(MONTH(Table1[[#This Row],[Hora de início]])<10,"0"&MONTH(Table1[[#This Row],[Hora de início]]),MONTH(Table1[[#This Row],[Hora de início]])) -> 2025/05 | J39: =VLOOKUP(Table1[[#This Row],[Área avaliada]],Endereços!A:B,2,0) -> Área Azul
A40: 39 | B40: 45785.399 | C40: 45785.399 | D40: JHOSLLEY | E40: Reg4Lata | G40: =VLOOKUP(F40,Produtos!A:B,2,FALSE) -> #N/A | H40: Avaria | I40: =YEAR(Table1[[#This Row],[Hora de início]])&"/"&IF(MONTH(Table1[[#This Row],[Hora de início]])<10,"0"&MONTH(Table1[[#This Row],[Hora de início]]),MONTH(Table1[[#This Row],[Hora de início]])) -> 2025/05 | J40: =VLOOKUP(Table1[[#This Row],[Área avaliada]],Endereços!A:B,2,0) -> Área Azul
A41: 40 | B41: 45785.402 | C41: 45785.402 | D41: JHOSLLEY | E41: Reg4Lata | G41: =VLOOKUP(F41,Produtos!A:B,2,FALSE) -> #N/A | H41: Avaria | I41: =YEAR(Table1[[#This Row],[Hora de início]])&"/"&IF(MONTH(Table1[[#This Row],[Hora de início]])<10,"0"&MONTH(Table1[[#This Row],[Hora de início]]),MONTH(Table1[[#This Row],[Hora de início]])) -> 2025/05 | J41: =VLOOKUP(Table1[[#This Row],[Área avaliada]],Endereços!A:B,2,0) -> Área Azul
A42: 41 | B42: 45785.403 | C42: 45785.404 | D42: JHOSLLEY | E42: Reg4Lata | G42: =VLOOKUP(F42,Produtos!A:B,2,FALSE) -> #N/A | H42: Avaria | I42: =YEAR(Table1[[#This Row],[Hora de início]])&"/"&IF(MONTH(Table1[[#This Row],[Hora de início]])<10,"0"&MONTH(Table1[[#This Row],[Hora de início]]),MONTH(Table1[[#This Row],[Hora de início]])) -> 2025/05 | J42: =VLOOKUP(Table1[[#This Row],[Área avaliada]],Endereços!A:B,2,0) -> Área Azul
A43: 42 | B43: 45785.407 | C43: 45785.408 | D43: JHOSLLEY | E43: Reg4Lata | G43: =VLOOKUP(F43,Produtos!A:B,2,FALSE) -> #N/A | H43: Avaria | I43: =YEAR(Table1[[#This Row],[Hora de início]])&"/"&IF(MONTH(Table1[[#This Row],[Hora de início]])<10,"0"&MONTH(Table1[[#This Row],[Hora de início]]),MONTH(Table1[[#This Row],[Hora de início]])) -> 2025/05 | J43: =VLOOKUP(Table1[[#This Row],[Área avaliada]],Endereços!A:B,2,0) -> Área Azul
...

Sheet Endereços
A1: Endereço | B1: Área
A2: Picking | B2: Picking Alto Giro
A3: Regulador 1 | B3: Área Verde
A4: RACK01 | B4: Área Verde
A5: Picking Baixo Giro | B5: Picking Baixo Giro
A6: Picking Alto Giro | B6: Picking Alto Giro
A7: Marketplace | B7: Área Vermelho
A8: Reg2RGB | B8: Área Azul
A9: Reg4Lata | B9: Área Azul
A10: RegPET | B10: Área Azul
A11: Camera F | B11: Área Vermelho
A12: Reg1RGBL | B12: Área Verde

Sheet Produtos
A1: Cod | B1: Descrição
A2: 29232 | B2: 51 ICE MACA VERDE GFA VD 275 ML FD 24
A3: 21529 | B3: ABSOLUT ORIGINAL GFA VIDRO 1L
A4: 24613 | B4: ACQUA PANNA S/G GARRAFA VD 505 ML CX 24
A5: 23463 | B5: AG MIN S GAS AMA PET 500ML C12 N SHAPE
A6: 13017 | B6: AGUA M F DA ILHA C/G PET 300 ML CX C/12
A7: 15416 | B7: AGUA M F DA ILHA C/G PET 500ML CXC12 PRE
A8: 6909 | B8: AGUA M F DA ILHA C/G PVC 2L CAIXA C/06
A9: 6905 | B9: AGUA M F DA ILHA C/G PVC 500ML CAIXA C/1
A10: 6911 | B10: AGUA M F DA ILHA S/G COPO 200ML CAIXA C/
A11: 8975 | B11: AGUA M F DA ILHA S/G GARRAF+O PET 5 LITROS CX C/04
A12: 15414 | B12: AGUA M F DA ILHA S/G PET 500ML CXC12 PRE
A13: 6907 | B13: AGUA M F DA ILHA S/G PVC 1,5L CAIXA C/06
... A424: 21391 | B424: ﾁGUA MINERAL S/ GﾁS AMA PET 1,5L CX 6 NP
