Workbook

Sheet Gestao
A1: ID | B1: Hora de início | C1: Hora de conclusão | D1: Nome do avaliador | E1: Área avaliada | F1: QUAL O ENDEREÇO? | G1: Código do produto | H1: Coluna1 | I1: Tipo incidente | J1: ANO/MÊS
A2: 1 | B2: 45722.406 | C2: 45722.407 | D2: RAFAEL | E2: Picking | H2: =VLOOKUP(G2,Produtos!A:B,2,FALSE) -> #N/A | J2: =YEAR(Table1[[#This Row],[Hora de início]])&"/"&IF(MONTH(Table1[[#This Row],[Hora de início]])<10,"0"&MONTH(Table1[[#This Row],[Hora de início]]),MONTH(Table1[[#This Row],[Hora de início]])) -> 2025/03
A3: 2 | B3: 45723.428 | C3: 45723.429 | D3: KETLYN | E3: Regulador 1 | H3: =VLOOKUP(G3,Produtos!A:B,2,FALSE) -> #N/A | J3: =YEAR(Table1[[#This Row],[Hora de início]])&"/"&IF(MONTH(Table1[[#This Row],[Hora de início]])<10,"0"&MONTH(Table1[[#This Row],[Hora de início]]),MONTH(Table1[[#This Row],[Hora de início]])) -> 2025/03
A4: 3 | B4: 45723.446 | C4: 45723.447 | D4: KETLYN | E4: Regulador 1 | H4: =VLOOKUP(G4,Produtos!A:B,2,FALSE) -> #N/A | J4: =YEAR(Table1[[#This Row],[Hora de início]])&"/"&IF(MONTH(Table1[[#This Row],[Hora de início]])<10,"0"&MONTH(Table1[[#This Row],[Hora de início]]),MONTH(Table1[[#This Row],[Hora de início]])) -> 2025/03
A5: 4 | B5: 45723.447 | C5: 45723.448 | D5: CLEBER | E5: Picking | H5: =VLOOKUP(G5,Produtos!A:B,2,FALSE) -> #N/A | J5: =YEAR(Table1[[#This Row],[Hora de início]])&"/"&IF(MONTH(Table1[[#This Row],[Hora de início]])<10,"0"&MONTH(Table1[[#This Row],[Hora de início]]),MONTH(Table1[[#This Row],[Hora de início]])) -> 2025/03
A6: 5 | B6: 45735.41 | C6: 45735.416 | D6: RAFAEL | E6: RACK01 | H6: =VLOOKUP(G6,Produtos!A:B,2,FALSE) -> #N/A | J6: =YEAR(Table1[[#This Row],[Hora de início]])&"/"&IF(MONTH(Table1[[#This Row],[Hora de início]])<10,"0"&MONTH(Table1[[#This Row],[Hora de início]]),MONTH(Table1[[#This Row],[Hora de início]])) -> 2025/03
A7: 6 | B7: 45735.416 | C7: 45735.417 | D7: TAINÁ | E7: Picking Baixo Giro | H7: =VLOOKUP(G7,Produtos!A:B,2,FALSE) -> #N/A | J7: =YEAR(Table1[[#This Row],[Hora de início]])&"/"&IF(MONTH(Table1[[#This Row],[Hora de início]])<10,"0"&MONTH(Table1[[#This Row],[Hora de início]]),MONTH(Table1[[#This Row],[Hora de início]])) -> 2025/03
A8: 7 | B8: 45735.454 | C8: 45735.456 | D8: RAFAEL | E8: Picking Alto Giro | H8: =VLOOKUP(G8,Produtos!A:B,2,FALSE) -> #N/A | J8: =YEAR(Table1[[#This Row],[Hora de início]])&"/"&IF(MONTH(Table1[[#This Row],[Hora de início]])<10,"0"&MONTH(Table1[[#This Row],[Hora de início]]),MONTH(Table1[[#This Row],[Hora de início]])) -> 2025/03
A9: 8 | B9: 45735.456 | C9: 45735.457 | D9: NARCISO | E9: Picking Baixo Giro | H9: =VLOOKUP(G9,Produtos!A:B,2,FALSE) -> #N/A | J9: =YEAR(Table1[[#This Row],[Hora de início]])&"/"&IF(MONTH(Table1[[#This Row],[Hora de início]])<10,"0"&MONTH(Table1[[#This Row],[Hora de início]]),MONTH(Table1[[#This Row],[Hora de início]])) -> 2025/03
A10: 9 | B10: 45735.457 | C10: 45735.458 | D10: JHOSLLEY | E10: Marketplace | H10: =VLOOKUP(G10,Produtos!A:B,2,FALSE) -> #N/A | J10: =YEAR(Table1[[#This Row],[Hora de início]])&"/"&IF(MONTH(Table1[[#This Row],[Hora de início]])<10,"0"&MONTH(Table1[[#This Row],[Hora de início]]),MONTH(Table1[[#This Row],[Hora de início]])) -> 2025/03
A11: 10 | B11: 45735.458 | C11: 45735.458 | D11: LUCIANE | E11: Reg2RGB | H11: =VLOOKUP(G11,Produtos!A:B,2,FALSE) -> #N/A | J11: =YEAR(Table1[[#This Row],[Hora de início]])&"/"&IF(MONTH(Table1[[#This Row],[Hora de início]])<10,"0"&MONTH(Table1[[#This Row],[Hora de início]]),MONTH(Table1[[#This Row],[Hora de início]])) -> 2025/03
A12: 11 | B12: 45735.459 | C12: 45735.46 | D12: BRUNO | E12: RACK01 | H12: =VLOOKUP(G12,Produtos!A:B,2,FALSE) -> #N/A | J12: =YEAR(Table1[[#This Row],[Hora de início]])&"/"&IF(MONTH(Table1[[#This Row],[Hora de início]])<10,"0"&MONTH(Table1[[#This Row],[Hora de início]]),MONTH(Table1[[#This Row],[Hora de início]])) -> 2025/03
A13: 12 | B13: 45735.46 | C13: 45735.461 | D13: CARLOS | E13: Reg4Lata | H13: =VLOOKUP(G13,Produtos!A:B,2,FALSE) -> #N/A | J13: =YEAR(Table1[[#This Row],[Hora de início]])&"/"&IF(MONTH(Table1[[#This Row],[Hora de início]])<10,"0"&MONTH(Table1[[#This Row],[Hora de início]]),MONTH(Table1[[#This Row],[Hora de início]])) -> 2025/03
... A58: 57 | B58: 45787.472 | C58: 45787.474 | D58: RAFAEL | E58: Camera F | H58: =VLOOKUP(G58,Produtos!A:B,2,FALSE) -> #N/A | J58: =YEAR(Table1[[#This Row],[Hora de início]])&"/"&IF(MONTH(Table1[[#This Row],[Hora de início]])<10,"0"&MONTH(Table1[[#This Row],[Hora de início]]),MONTH(Table1[[#This Row],[Hora de início]])) -> 2025/05
A59: 58 | B59: 45789.399 | C59: 45789.4 | D59: JHOSLLEY | E59: Reg4Lata | G59: 9089 | H59: =VLOOKUP(G59,Produtos!A:B,2,FALSE) -> SUKITA LATA 350ML SH C/12 NPAL | I59: Produto avariado-embal.primária | J59: =YEAR(Table1[[#This Row],[Hora de início]])&"/"&IF(MONTH(Table1[[#This Row],[Hora de início]])<10,"0"&MONTH(Table1[[#This Row],[Hora de início]]),MONTH(Table1[[#This Row],[Hora de início]])) -> 2025/05
A60: 59 | B60: 45789.401 | C60: 45789.402 | D60: JHOSLLEY | E60: Reg4Lata | G60: 9087 | H60: =VLOOKUP(G60,Produtos!A:B,2,FALSE) -> SODA LIMONADA ANTAR LT350ML SH C/12 NPAL | I60: Produto avariado-embal.primária | J60: =YEAR(Table1[[#This Row],[Hora de início]])&"/"&IF(MONTH(Table1[[#This Row],[Hora de início]])<10,"0"&MONTH(Table1[[#This Row],[Hora de início]]),MONTH(Table1[[#This Row],[Hora de início]])) -> 2025/05
A61: 60 | B61: 45789.402 | C61: 45789.403 | D61: JHOSLLEY | E61: Reg4Lata | G61: 20651 | H61: =VLOOKUP(G61,Produtos!A:B,2,FALSE) -> CORONA N LT SLEEK 350ML CX 8 | I61: Produto avariado-embal.primária | J61: =YEAR(Table1[[#This Row],[Hora de início]])&"/"&IF(MONTH(Table1[[#This Row],[Hora de início]])<10,"0"&MONTH(Table1[[#This Row],[Hora de início]]),MONTH(Table1[[#This Row],[Hora de início]])) -> 2025/05
A62: 61 | B62: 45789.404 | C62: 45789.405 | D62: JHOSLLEY | E62: Reg4Lata | G62: 17808 | H62: =VLOOKUP(G62,Produtos!A:B,2,FALSE) -> BUDWEISER OW 330ML CX C 24 | I62: Produto avariado-embal.primária | J62: =YEAR(Table1[[#This Row],[Hora de início]])&"/"&IF(MONTH(Table1[[#This Row],[Hora de início]])<10,"0"&MONTH(Table1[[#This Row],[Hora de início]]),MONTH(Table1[[#This Row],[Hora de início]])) -> 2025/05
A63: 62 | B63: 45789.406 | C63: 45789.407 | D63: JHOSLLEY | E63: Reg4Lata | G63: 20498 | H63: =VLOOKUP(G63,Produtos!A:B,2,FALSE) -> BRAHMA DUPLO MALTE LT SLEEK 350ML SH C12 | I63: Produto avariado-embal.primária | J63: =YEAR(Table1[[#This Row],[Hora de início]])&"/"&IF(MONTH(Table1[[#This Row],[Hora de início]])<10,"0"&MONTH(Table1[[#This Row],[Hora de início]]),MONTH(Table1[[#This Row],[Hora de início]])) -> 2025/05
A64: 63 | B64: 45789.648 | C64: 45789.655 | D64: JOSÉ GILNEI | E64: Picking Baixo Giro | H64: =VLOOKUP(G64,Produtos!A:B,2,FALSE) -> #N/A | I64: Produto avariado-embal.primária | J64: =YEAR(Table1[[#This Row],[Hora de início]])&"/"&IF(MONTH(Table1[[#This Row],[Hora de início]])<10,"0"&MONTH(Table1[[#This Row],[Hora de início]]),MONTH(Table1[[#This Row],[Hora de início]])) -> 2025/05
A65: 64 | B65: 45790.39 | C65: 45790.395 | D65: LUCIANE | E65: Reg4Lata | G65: 2353 | H65: =VLOOKUP(G65,Produtos!A:B,2,FALSE) -> GUARANA CHP ANTARCTICA DIET PET 2L CXC/6 | I65: Produto avariado/embal.segundária | J65: =YEAR(Table1[[#This Row],[Hora de início]])&"/"&IF(MONTH(Table1[[#This Row],[Hora de início]])<10,"0"&MONTH(Table1[[#This Row],[Hora de início]]),MONTH(Table1[[#This Row],[Hora de início]])) -> 2025/05
A66: 65 | B66: 45790.398 | C66: 45790.4 | D66: LUCIANE | E66: Reg4Lata | H66: =VLOOKUP(G66,Produtos!A:B,2,FALSE) -> #N/A | I66: Produto avariado/embal.segundária | J66: =YEAR(Table1[[#This Row],[Hora de início]])&"/"&IF(MONTH(Table1[[#This Row],[Hora de início]])<10,"0"&MONTH(Table1[[#This Row],[Hora de início]]),MONTH(Table1[[#This Row],[Hora de início]])) -> 2025/05
A67: 66 | B67: 45790.402 | C67: 45790.404 | D67: LUCIANE | E67: Reg4Lata | G67: 28137 | H67: =VLOOKUP(G67,Produtos!A:B,2,FALSE) -> SKOL BT CAIPIRINHA LT 269ML CX CA C/8 NP | I67: Microfuro | J67: =YEAR(Table1[[#This Row],[Hora de início]])&"/"&IF(MONTH(Table1[[#This Row],[Hora de início]])<10,"0"&MONTH(Table1[[#This Row],[Hora de início]]),MONTH(Table1[[#This Row],[Hora de início]])) -> 2025/05
A68: 67 | B68: 45790.404 | C68: 45790.405 | D68: LUCIANE | E68: Reg4Lata | G68: 33734 | H68: =VLOOKUP(G68,Produtos!A:B,2,FALSE) -> BEATS RED MIX LT 269ML SH C/8 | I68: Microfuro | J68: =YEAR(Table1[[#This Row],[Hora de início]])&"/"&IF(MONTH(Table1[[#This Row],[Hora de início]])<10,"0"&MONTH(Table1[[#This Row],[Hora de início]]),MONTH(Table1[[#This Row],[Hora de início]])) -> 2025/05
A69: 68 | B69: 45790.407 | C69: 45790.408 | D69: LUCIANE | E69: Reg4Lata | G69: 22180 | H69: =VLOOKUP(G69,Produtos!A:B,2,FALSE) -> BUDWEISER ZERO LN 330ML SIX-PACK SH C/4 | I69: Produto avariado/embal.segundária | J69: =YEAR(Table1[[#This Row],[Hora de início]])&"/"&IF(MONTH(Table1[[#This Row],[Hora de início]])<10,"0"&MONTH(Table1[[#This Row],[Hora de início]]),MONTH(Table1[[#This Row],[Hora de início]])) -> 2025/05
A70: 69 | B70: 45791.606 | C70: 45791.607 | D70: JHOSLLEY | E70: Reg4Lata | G70: 9274 | H70: =VLOOKUP(G70,Produtos!A:B,2,FALSE) -> PEPSI ZERO LATA 350ML SH C/12 NPAL | I70: Produto avariado-embal.primária | J70: =YEAR(Table1[[#This Row],[Hora de início]])&"/"&IF(MONTH(Table1[[#This Row],[Hora de início]])<10,"0"&MONTH(Table1[[#This Row],[Hora de início]]),MONTH(Table1[[#This Row],[Hora de início]])) -> 2025/05
A71: 70 | B71: 45791.614 | C71: 45791.615 | D71: JHOSLLEY | E71: Reg4Lata | G71: 14135 | H71: =VLOOKUP(G71,Produtos!A:B,2,FALSE) -> BUDWEISER LT 473ML SIX-PACK SH C/2 NPAL | I71: Produto avariado-embal.primária | J71: =YEAR(Table1[[#This Row],[Hora de início]])&"/"&IF(MONTH(Table1[[#This Row],[Hora de início]])<10,"0"&MONTH(Table1[[#This Row],[Hora de início]]),MONTH(Table1[[#This Row],[Hora de início]])) -> 2025/05
A72: 71 | B72: 45794.253 | C72: 45794.253 | D72: JHOSLLEY | E72: RegPET | G72: 9084 | H72: =VLOOKUP(G72,Produtos!A:B,2,FALSE) -> GUARANA CHP ANTARCT LT350ML SH C/12 NPAL | I72: Produto avariado-embal.primária | J72: =YEAR(Table1[[#This Row],[Hora de início]])&"/"&IF(MONTH(Table1[[#This Row],[Hora de início]])<10,"0"&MONTH(Table1[[#This Row],[Hora de início]]),MONTH(Table1[[#This Row],[Hora de início]])) -> 2025/05
A73: 72 | B73: 45794.254 | C73: 45794.255 | D73: JHOSLLEY | E73: Reg4Lata | G73: 14135 | H73: =VLOOKUP(G73,Produtos!A:B,2,FALSE) -> BUDWEISER LT 473ML SIX-PACK SH C/2 NPAL | I73: Produto avariado-embal.primária | J73: =YEAR(Table1[[#This Row],[Hora de início]])&"/"&IF(MONTH(Table1[[#This Row],[Hora de início]])<10,"0"&MONTH(Table1[[#This Row],[Hora de início]]),MONTH(Table1[[#This Row],[Hora de início]])) -> 2025/05
A74: 73 | B74: 45794.258 | C74: 45794.259 | D74: JHOSLLEY | E74: Reg4Lata | G74: 20498 | H74: =VLOOKUP(G74,Produtos!A:B,2,FALSE) -> BRAHMA DUPLO MALTE LT SLEEK 350ML SH C12 | I74: Produto avariado-embal.primária | J74: =YEAR(Table1[[#This Row],[Hora de início]])&"/"&IF(MONTH(Table1[[#This Row],[Hora de início]])<10,"0"&MONTH(Table1[[#This Row],[Hora de início]]),MONTH(Table1[[#This Row],[Hora de início]])) -> 2025/05
A75: 74 | B75: 45794.259 | C75: 45794.26 | D75: JHOSLLEY | E75: Reg4Lata | G75: 17808 | H75: =VLOOKUP(G75,Produtos!A:B,2,FALSE) -> BUDWEISER OW 330ML CX C 24 | I75: Produto avariado-embal.primária | J75: =YEAR(Table1[[#This Row],[Hora de início]])&"/"&IF(MONTH(Table1[[#This Row],[Hora de início]])<10,"0"&MONTH(Table1[[#This Row],[Hora de início]]),MONTH(Table1[[#This Row],[Hora de início]])) -> 2025/05
A76: 75 | B76: 45794.447 | C76: 45794.448 | D76: RAFAEL | E76: Camera F | H76: =VLOOKUP(G76,Produtos!A:B,2,FALSE) -> #N/A | J76: =YEAR(Table1[[#This Row],[Hora de início]])&"/"&IF(MONTH(Table1[[#This Row],[Hora de início]])<10,"0"&MONTH(Table1[[#This Row],[Hora de início]]),MONTH(Table1[[#This Row],[Hora de início]])) -> 2025/05
A77: 76 | B77: 45794.609 | C77: 45794.613 | D77: JOSÉ GILNEI | E77: Marketplace | H77: =VLOOKUP(G77,Produtos!A:B,2,FALSE) -> #N/A | I77: Lote e conformidade | J77: =YEAR(Table1[[#This Row],[Hora de início]])&"/"&IF(MONTH(Table1[[#This Row],[Hora de início]])<10,"0"&MONTH(Table1[[#This Row],[Hora de início]]),MONTH(Table1[[#This Row],[Hora de início]])) -> 2025/05
A78: 77 | B78: 45797.381 | C78: 45797.382 | D78: JHOSLLEY | E78: Reg4Lata | G78: 7982 | H78: =VLOOKUP(G78,Produtos!A:B,2,FALSE) -> GATORADE LIMAO PET 500ML SIX PACK | I78: Palete quebrado | J78: =YEAR(Table1[[#This Row],[Hora de início]])&"/"&IF(MONTH(Table1[[#This Row],[Hora de início]])<10,"0"&MONTH(Table1[[#This Row],[Hora de início]]),MONTH(Table1[[#This Row],[Hora de início]])) -> 2025/05
A79: 78 | B79: 45797.386 | C79: 45797.386 | D79: JHOSLLEY | E79: Reg4Lata | G79: 17808 | H79: =VLOOKUP(G79,Produtos!A:B,2,FALSE) -> BUDWEISER OW 330ML CX C 24 | I79: Produto avariado-embal.primária | J79: =YEAR(Table1[[#This Row],[Hora de início]])&"/"&IF(MONTH(Table1[[#This Row],[Hora de início]])<10,"0"&MONTH(Table1[[#This Row],[Hora de início]]),MONTH(Table1[[#This Row],[Hora de início]])) -> 2025/05
A80: 79 | B80: 45798.408 | C80: 45798.408 | D80: JHOSLLEY | E80: Reg4Lata | G80: 32500 | H80: =VLOOKUP(G80,Produtos!A:B,2,FALSE) -> STELLA ART PUR GOLD LT SL 350ML C8 CX CT | I80: Produto avariado-embal.primária | J80: =YEAR(Table1[[#This Row],[Hora de início]])&"/"&IF(MONTH(Table1[[#This Row],[Hora de início]])<10,"0"&MONTH(Table1[[#This Row],[Hora de início]]),MONTH(Table1[[#This Row],[Hora de início]])) -> 2025/05
A81: 80 | B81: 45798.411 | C81: 45798.411 | D81: JHOSLLEY | E81: Reg4Lata | G81: 9089 | H81: =VLOOKUP(G81,Produtos!A:B,2,FALSE) -> SUKITA LATA 350ML SH C/12 NPAL | I81: Produto avariado-embal.primária | J81: =YEAR(Table1[[#This Row],[Hora de início]])&"/"&IF(MONTH(Table1[[#This Row],[Hora de início]])<10,"0"&MONTH(Table1[[#This Row],[Hora de início]]),MONTH(Table1[[#This Row],[Hora de início]])) -> 2025/05
A82: 81 | B82: 45798.413 | C82: 45798.414 | D82: JHOSLLEY | E82: Reg4Lata | G82: 2354 | H82: =VLOOKUP(G82,Produtos!A:B,2,FALSE) -> SODA LIMONADA ANTARCT DIET PET 2L CX C/6 | I82: Produto avariado-embal.primária | J82: =YEAR(Table1[[#This Row],[Hora de início]])&"/"&IF(MONTH(Table1[[#This Row],[Hora de início]])<10,"0"&MONTH(Table1[[#This Row],[Hora de início]]),MONTH(Table1[[#This Row],[Hora de início]])) -> 2025/05
A83: 82 | B83: 45798.417 | C83: 45798.419 | D83: LUCIANE | E83: Reg2RGB | G83: 9067 | H83: =VLOOKUP(G83,Produtos!A:B,2,FALSE) -> ANTARCTICA PILSEN LATA 350ML SH C/12 NPA | I83: Microfuro | J83: =YEAR(Table1[[#This Row],[Hora de início]])&"/"&IF(MONTH(Table1[[#This Row],[Hora de início]])<10,"0"&MONTH(Table1[[#This Row],[Hora de início]]),MONTH(Table1[[#This Row],[Hora de início]])) -> 2025/05
A84: 83 | B84: 45798.422 | C84: 45798.423 | D84: LUCIANE | E84: Reg4Lata | G84: 9069 | H84: =VLOOKUP(G84,Produtos!A:B,2,FALSE) -> BRAHMA CHOPP LATA 350ML SH C/12 NPAL | I84: Microfuro | J84: =YEAR(Table1[[#This Row],[Hora de início]])&"/"&IF(MONTH(Table1[[#This Row],[Hora de início]])<10,"0"&MONTH(Table1[[#This Row],[Hora de início]]),MONTH(Table1[[#This Row],[Hora de início]])) -> 2025/05
...

Sheet Produtos
A1: Cod | B1: Descrição
A2: 29232 | B2: 51 ICE MACA VERDE GFA VD 275 ML FD 24
A3: 21529 | B3: ABSOLUT ORIGINAL GFA VIDRO 1L
A4: 24613 | B4: ACQUA PANNA S/G GARRAFA VD 505 ML CX 24
A5: 23463 | B5: AG MIN S GAS AMA PET 500ML C12 N SHAPE
A6: 13017 | B6: AGUA M F DA ILHA C/G PET 300 ML CX C/12
A7: 15416 | B7: AGUA M F DA ILHA C/G PET 500ML CXC12 PRE
A8: 6909 | B8: AGUA M F DA ILHA C/G PVC 2L CAIXA C/06
A9: 6905 | B9: AGUA M F DA ILHA C/G PVC 500ML CAIXA C/1
A10: 6911 | B10: AGUA M F DA ILHA S/G COPO 200ML CAIXA C/
A11: 8975 | B11: AGUA M F DA ILHA S/G GARRAF+O PET 5 LITROS CX C/04
A12: 15414 | B12: AGUA M F DA ILHA S/G PET 500ML CXC12 PRE
A13: 6907 | B13: AGUA M F DA ILHA S/G PVC 1,5L CAIXA C/06
... A424: 21391 | B424: ﾁGUA MINERAL S/ GﾁS AMA PET 1,5L CX 6 NP
